[2018-05-01 21:47:27,163] ERROR in app: Exception on /get_info [POST]
Traceback (most recent call last):
  File "C:\Users\Inspiron\Anaconda2\envs\py25\lib\site-packages\flask\app.py", line 1982, in wsgi_app
    response = self.full_dispatch_request()
  File "C:\Users\Inspiron\Anaconda2\envs\py25\lib\site-packages\flask\app.py", line 1614, in full_dispatch_request
    rv = self.handle_user_exception(e)
  File "C:\Users\Inspiron\Anaconda2\envs\py25\lib\site-packages\flask\app.py", line 1517, in handle_user_exception
    reraise(exc_type, exc_value, tb)
  File "C:\Users\Inspiron\Anaconda2\envs\py25\lib\site-packages\flask\_compat.py", line 33, in reraise
    raise value
  File "C:\Users\Inspiron\Anaconda2\envs\py25\lib\site-packages\flask\app.py", line 1612, in full_dispatch_request
    rv = self.dispatch_request()
  File "C:\Users\Inspiron\Anaconda2\envs\py25\lib\site-packages\flask\app.py", line 1598, in dispatch_request
    return self.view_functions[rule.endpoint](**req.view_args)
  File "main.py", line 81, in info
    answer = agent.handle_message(query, sender_id = "user")
  File "C:\Users\Inspiron\Anaconda2\envs\py25\lib\site-packages\rasa_core\agent.py", line 101, in handle_message
    UserMessage(text_message, output_channel, sender_id))
  File "C:\Users\Inspiron\Anaconda2\envs\py25\lib\site-packages\rasa_core\processor.py", line 82, in handle_message
    self._handle_message_with_tracker(message, tracker)
  File "C:\Users\Inspiron\Anaconda2\envs\py25\lib\site-packages\rasa_core\processor.py", line 223, in _handle_message_with
    parse_data = self._parse_message(message)
  File "C:\Users\Inspiron\Anaconda2\envs\py25\lib\site-packages\rasa_core\processor.py", line 212, in _parse_message
    parse_data = self.interpreter.parse(message.text)
  File "C:\Users\Inspiron\Anaconda2\envs\py25\lib\site-packages\rasa_core\interpreter.py", line 230, in parse
    return self.interpreter.parse(text)
  File "C:\Users\Inspiron\Anaconda2\envs\py25\lib\site-packages\rasa_nlu\model.py", line 295, in parse
    component.process(message, **self.context)
  File "C:\Users\Inspiron\Anaconda2\envs\py25\lib\site-packages\rasa_nlu\classifiers\sklearn_intent_classifier.py", line 1
    intent_ids, probabilities = self.predict(X)
  File "C:\Users\Inspiron\Anaconda2\envs\py25\lib\site-packages\rasa_nlu\classifiers\sklearn_intent_classifier.py", line 1
    pred_result = self.predict_prob(X)
  File "C:\Users\Inspiron\Anaconda2\envs\py25\lib\site-packages\rasa_nlu\classifiers\sklearn_intent_classifier.py", line 1
    return self.clf.predict_proba(X)
  File "C:\Users\Inspiron\Anaconda2\envs\py25\lib\site-packages\sklearn\utils\metaestimators.py", line 115, in <lambda>
    out = lambda *args, **kwargs: self.fn(obj, *args, **kwargs)
  File "C:\Users\Inspiron\Anaconda2\envs\py25\lib\site-packages\sklearn\model_selection\_search.py", line 484, in predict_
    return self.best_estimator_.predict_proba(X)
  File "C:\Users\Inspiron\Anaconda2\envs\py25\lib\site-packages\sklearn\svm\base.py", line 594, in _predict_proba
    X = self._validate_for_predict(X)
  File "C:\Users\Inspiron\Anaconda2\envs\py25\lib\site-packages\sklearn\svm\base.py", line 459, in _validate_for_predict
    (n_features, self.shape_fit_[1]))
ValueError: X.shape[1] = 300 should be equal to 384, the number of features at training time